INFO:root:Посещена страница 'о себе'
INFO:root:Посещена страница 'о себе'
INFO:django.utils.autoreload:C:\Users\Aleksandr\PycharmProjects\Django_ptoject\myproject\myproject\settings.py changed, reloading.
INFO:root:Посещена страница 'о себе'
INFO:django.server:"GET /about/ HTTP/1.1" 200 308
INFO:root:Посещена страница 'о себе'
INFO:django.server:"GET /about/ HTTP/1.1" 200 308
INFO:root:Посещена страница 'о себе'
INFO:django.server:"GET /about/ HTTP/1.1" 200 308
INFO:root:Посещена страница 'о себе'
INFO:django.server:"GET /about/ HTTP/1.1" 200 308
INFO:root:Посещена страница 'о себе'
INFO:django.server:"GET /about/ HTTP/1.1" 200 308
INFO:root:Посещена главная страница
INFO:django.server:"GET / HTTP/1.1" 200 388
INFO:root:Посещена страница 'о себе'
INFO:django.server:"GET /about/ HTTP/1.1" 200 308
INFO:root:Посещена главная страница
INFO:django.server:"GET / HTTP/1.1" 200 388
INFO:root:Посещена главная страница
INFO:django.server:"GET / HTTP/1.1" 200 388
INFO:root:Посещена главная страница
INFO:django.server:"GET / HTTP/1.1" 200 388
INFO:root:Посещена главная страница
INFO:django.server:"GET / HTTP/1.1" 200 388
INFO:root:Посещена главная страница
INFO:django.server:"GET / HTTP/1.1" 200 388
INFO:root:Посещена главная страница
INFO:django.server:"GET / HTTP/1.1" 200 388
INFO:root:Посещена главная страница
INFO:django.server:"GET / HTTP/1.1" 200 388
INFO:root:Посещена страница 'о себе'
INFO:django.server:"GET /about/ HTTP/1.1" 200 308
INFO:root:Посещена страница 'о себе'
INFO:django.server:"GET /about/ HTTP/1.1" 200 308
INFO:root:Посещена страница 'о себе'
INFO:django.server:"GET /about/ HTTP/1.1" 200 308
INFO:root:Посещена главная страница
INFO:django.server:"GET / HTTP/1.1" 200 388
INFO:root:Посещена главная страница
INFO:django.server:"GET / HTTP/1.1" 200 388
INFO:root:Посещена главная страница
INFO:django.server:"GET / HTTP/1.1" 200 388
INFO:root:Посещена страница 'о себе'
INFO:django.server:"GET /about/ HTTP/1.1" 200 308
INFO:root:Посещена главная страница
INFO:django.server:"GET / HTTP/1.1" 200 388
WARNING:django.request:Not Found: /favicon.ico
WARNING:django.server:"GET /favicon.ico HTTP/1.1" 404 2548
INFO:root:Посещена страница 'о себе'
INFO:django.server:"GET /about/ HTTP/1.1" 200 308
INFO:django.server:"GET /admin/ HTTP/1.1" 302 0
INFO:django.server:"GET /admin/login/?next=/admin/ HTTP/1.1" 200 4158
INFO:django.server:"GET /static/admin/css/base.css HTTP/1.1" 304 0
INFO:django.server:"GET /static/admin/css/dark_mode.css HTTP/1.1" 304 0
INFO:django.server:"GET /static/admin/css/nav_sidebar.css HTTP/1.1" 304 0
INFO:django.server:"GET /static/admin/css/login.css HTTP/1.1" 304 0
INFO:django.server:"GET /static/admin/css/responsive.css HTTP/1.1" 304 0
INFO:django.server:"GET /static/admin/js/theme.js HTTP/1.1" 304 0
INFO:django.server:"GET /static/admin/js/nav_sidebar.js HTTP/1.1" 304 0
WARNING:django.request:Not Found: /myapp2/
WARNING:django.server:"GET /myapp2/ HTTP/1.1" 404 2536
INFO:root:Посещена страница myapp2
INFO:django.server:"GET /myapp3/ HTTP/1.1" 200 337
INFO:django.utils.autoreload:C:\Users\Aleksandr\PycharmProjects\Django_project_2\myproject\myapp3\views.py changed, reloading.
INFO:root:Посещена страница myapp2
INFO:django.server:"GET /myapp3/ HTTP/1.1" 200 337
INFO:root:Посещена страница myapp2
INFO:django.server:"GET /myapp3/ HTTP/1.1" 200 337
INFO:root:Посещена главная страница
INFO:django.server:"GET / HTTP/1.1" 200 388
INFO:root:Посещена главная страница
INFO:django.server:"GET / HTTP/1.1" 200 388
WARNING:django.request:Not Found: /myapp2/
WARNING:django.server:"GET /myapp2/ HTTP/1.1" 404 2536
INFO:root:Посещена страница myapp2
INFO:django.server:"GET /myapp3/ HTTP/1.1" 200 337
INFO:root:Посещена страница myapp2
INFO:django.server:"GET /myapp3/ HTTP/1.1" 200 337
INFO:django.utils.autoreload:C:\Users\Aleksandr\PycharmProjects\Django_project_2\myproject\myapp3\views.py changed, reloading.
INFO:root:Посещена страница myapp2
INFO:django.server:"GET /myapp3/ HTTP/1.1" 200 337
INFO:django.server:"GET /myapp3/client_orders/3/ HTTP/1.1" 200 412
INFO:django.server:"GET /myapp3/client_orders/1/ HTTP/1.1" 200 412
INFO:django.server:"GET /myapp3/client_orders/2/ HTTP/1.1" 200 412
INFO:django.server:"GET /myapp3/client_orders/10/ HTTP/1.1" 200 412
ERROR:django.request:Internal Server Error: /myapp3/client_orders/52/
Traceback (most recent call last):
  File "C:\Users\Aleksandr\PycharmProjects\Django_project_2\venv\lib\site-packages\django\core\handlers\exception.py", line 55, in inner
    response = get_response(request)
  File "C:\Users\Aleksandr\PycharmProjects\Django_project_2\venv\lib\site-packages\django\core\handlers\base.py", line 197, in _get_response
    response = wrapped_callback(request, *callback_args, **callback_kwargs)
  File "C:\Users\Aleksandr\PycharmProjects\Django_project_2\myproject\myapp3\views.py", line 11, in client_orders
    client = Client.objects.get(pk=client_id)
  File "C:\Users\Aleksandr\PycharmProjects\Django_project_2\venv\lib\site-packages\django\db\models\manager.py", line 87, in manager_method
    return getattr(self.get_queryset(), name)(*args, **kwargs)
  File "C:\Users\Aleksandr\PycharmProjects\Django_project_2\venv\lib\site-packages\django\db\models\query.py", line 649, in get
    raise self.model.DoesNotExist(
myapp3.models.Client.DoesNotExist: Client matching query does not exist.
ERROR:django.server:"GET /myapp3/client_orders/52/ HTTP/1.1" 500 74918
INFO:django.server:"GET /myapp3/client_orders/5/ HTTP/1.1" 200 412
INFO:django.server:"GET /myapp3/client_orders/5/ HTTP/1.1" 200 412
INFO:django.server:"GET /myapp3/client_orders/5/ HTTP/1.1" 200 412
INFO:django.server:"GET /myapp3/client_orders/5/ HTTP/1.1" 200 412
INFO:django.server:"GET /myapp3/client_orders/42 HTTP/1.1" 301 0
ERROR:django.request:Internal Server Error: /myapp3/client_orders/42/
Traceback (most recent call last):
  File "C:\Users\Aleksandr\PycharmProjects\Django_project_2\venv\lib\site-packages\django\core\handlers\exception.py", line 55, in inner
    response = get_response(request)
  File "C:\Users\Aleksandr\PycharmProjects\Django_project_2\venv\lib\site-packages\django\core\handlers\base.py", line 197, in _get_response
    response = wrapped_callback(request, *callback_args, **callback_kwargs)
  File "C:\Users\Aleksandr\PycharmProjects\Django_project_2\myproject\myapp3\views.py", line 11, in client_orders
    client = Client.objects.get(pk=client_id)
  File "C:\Users\Aleksandr\PycharmProjects\Django_project_2\venv\lib\site-packages\django\db\models\manager.py", line 87, in manager_method
    return getattr(self.get_queryset(), name)(*args, **kwargs)
  File "C:\Users\Aleksandr\PycharmProjects\Django_project_2\venv\lib\site-packages\django\db\models\query.py", line 649, in get
    raise self.model.DoesNotExist(
myapp3.models.Client.DoesNotExist: Client matching query does not exist.
ERROR:django.server:"GET /myapp3/client_orders/42/ HTTP/1.1" 500 74918
INFO:django.server:"GET /myapp3/client_orders/4/ HTTP/1.1" 200 412
INFO:django.utils.autoreload:C:\Users\Aleksandr\PycharmProjects\Django_project_2\myproject\myapp3\views.py changed, reloading.
INFO:django.server:"GET /myapp3/client_orders/4/ HTTP/1.1" 200 412
INFO:django.server:"GET /myapp3/client_orders/4/ HTTP/1.1" 200 412
INFO:django.server:"GET /myapp3/client_orders/4/ HTTP/1.1" 200 436
INFO:django.utils.autoreload:C:\Users\Aleksandr\PycharmProjects\Django_project_2\myproject\myapp3\views.py changed, reloading.
INFO:django.server:"GET /myapp3/client_orders/4/ HTTP/1.1" 200 412
INFO:django.server:"GET /myapp3/client_orders/4/ HTTP/1.1" 200 412
INFO:django.server:"GET /myapp3/client_orders/4/ HTTP/1.1" 200 412
INFO:django.server:"GET /myapp3/client_orders/4/ HTTP/1.1" 200 412
INFO:django.server:"GET /myapp3/client_orders/4/ HTTP/1.1" 200 412
INFO:django.server:"GET /myapp3/client_orders/4/ HTTP/1.1" 200 412
INFO:django.server:"GET /myapp3/client_orders/4/ HTTP/1.1" 200 412
INFO:django.server:"GET /myapp3/client_orders/4/ HTTP/1.1" 200 412
INFO:root:Посещена главная страница
INFO:django.server:"GET / HTTP/1.1" 200 388
WARNING:django.request:Not Found: /myapp2/
WARNING:django.server:"GET /myapp2/ HTTP/1.1" 404 2536
WARNING:django.request:Not Found: /myapp2/3
WARNING:django.server:"GET /myapp2/3 HTTP/1.1" 404 2539
WARNING:django.request:Not Found: /myapp2/
WARNING:django.server:"GET /myapp2/ HTTP/1.1" 404 2536
WARNING:django.request:Not Found: /myapp2/client_orders/5/
WARNING:django.server:"GET /myapp2/client_orders/5/ HTTP/1.1" 404 2584
INFO:django.server:"GET /myapp3/client_orders/5/ HTTP/1.1" 200 412
INFO:django.server:"GET /myapp3/client_orders/5/ HTTP/1.1" 200 412
INFO:django.server:"GET /myapp3/client_orders/5/ HTTP/1.1" 200 412
INFO:django.server:"GET /myapp3/client_orders/5/ HTTP/1.1" 200 412
INFO:django.server:"GET /myapp3/client_orders/5/ HTTP/1.1" 200 412
INFO:django.server:"GET /myapp3/client_orders/5/ HTTP/1.1" 200 412
INFO:django.server:"GET /myapp3/client_orders/5/ HTTP/1.1" 200 412
INFO:django.server:"GET /myapp3/client_orders/5/ HTTP/1.1" 200 412
INFO:django.server:"GET /myapp3/client_orders/5/ HTTP/1.1" 200 412
INFO:django.server:"GET /myapp3/client_orders/5/ HTTP/1.1" 200 412
INFO:django.utils.autoreload:C:\Users\Aleksandr\PycharmProjects\Django_project_2\myproject\myapp3\views.py changed, reloading.
INFO:django.server:"GET /myapp3/client_orders/5/ HTTP/1.1" 200 412
INFO:django.server:"GET /myapp3/client_orders/5/ HTTP/1.1" 200 412
INFO:django.server:"GET /myapp3/client_orders/5/ HTTP/1.1" 200 412
INFO:django.server:"GET /myapp3/client_orders/5/ HTTP/1.1" 200 412
INFO:django.server:"GET /myapp3/client_orders/5/ HTTP/1.1" 200 412
INFO:django.server:"GET /myapp3/client_orders/5/ HTTP/1.1" 200 412
INFO:django.server:"GET /myapp3/client_orders/5/ HTTP/1.1" 200 412
INFO:django.server:"GET /myapp3/client_orders/5/ HTTP/1.1" 200 412
INFO:django.server:"GET /myapp3/client_orders/5/ HTTP/1.1" 200 412
INFO:django.server:"GET /myapp3/client_orders/5/ HTTP/1.1" 200 412
INFO:django.server:"GET /myapp3/client_orders/5/ HTTP/1.1" 200 412
INFO:django.server:"GET /myapp3/client_orders/5/ HTTP/1.1" 200 412
INFO:django.server:"GET /myapp3/client_orders/5/ HTTP/1.1" 200 412
INFO:django.server:"GET /myapp3/client_orders/5/ HTTP/1.1" 200 412
WARNING:django.request:Not Found: /myapp3/client_orders/
WARNING:django.server:"GET /myapp3/client_orders/ HTTP/1.1" 404 2852
INFO:django.server:"GET /myapp3/client_orders/10/ HTTP/1.1" 200 412
INFO:django.utils.autoreload:C:\Users\Aleksandr\PycharmProjects\Django_project_2\myproject\myproject\urls.py changed, reloading.
INFO:django.server:"GET /myapp3/client_orders/10/ HTTP/1.1" 200 412
INFO:django.server:"GET /myapp3/client_orders/10/ HTTP/1.1" 200 412
INFO:django.server:"GET /myapp3/client_orders/10/ HTTP/1.1" 200 412
INFO:django.server:"GET /myapp3/client_orders/10/ HTTP/1.1" 200 412
INFO:django.server:"GET /myapp3/client_orders/10/ HTTP/1.1" 200 412
INFO:django.server:"GET /myapp3/client_orders/10/ HTTP/1.1" 200 412
INFO:django.server:"GET /myapp3/client_orders/10/ HTTP/1.1" 200 360
INFO:django.server:"GET /myapp3/client_orders/10/ HTTP/1.1" 200 360
INFO:django.server:"GET /myapp3/client_orders/10/ HTTP/1.1" 200 360
INFO:django.server:"GET /myapp3/client_orders/10/ HTTP/1.1" 200 360
INFO:django.server:"GET /myapp3/client_orders/10/ HTTP/1.1" 200 360
INFO:django.server:"GET /myapp3/client_orders/10/ HTTP/1.1" 200 360
INFO:django.server:"GET /myapp3/client_orders/10/ HTTP/1.1" 200 360
INFO:django.utils.autoreload:C:\Users\Aleksandr\PycharmProjects\Django_project_2\myproject\myapp3\views.py changed, reloading.
INFO:django.utils.autoreload:C:\Users\Aleksandr\PycharmProjects\Django_project_2\myproject\myapp3\views.py changed, reloading.
INFO:django.utils.autoreload:C:\Users\Aleksandr\PycharmProjects\Django_project_2\myproject\myapp3\views.py changed, reloading.
ERROR:django.request:Internal Server Error: /myapp3/client_orders/10/
Traceback (most recent call last):
  File "C:\Users\Aleksandr\PycharmProjects\Django_project_2\venv\lib\site-packages\django\core\handlers\exception.py", line 55, in inner
    response = get_response(request)
  File "C:\Users\Aleksandr\PycharmProjects\Django_project_2\venv\lib\site-packages\django\core\handlers\base.py", line 197, in _get_response
    response = wrapped_callback(request, *callback_args, **callback_kwargs)
  File "C:\Users\Aleksandr\PycharmProjects\Django_project_2\myproject\myapp3\views.py", line 18, in client_orders
    seven_days_ago = timezone.now() - timedelta(days=7)
NameError: name 'timezone' is not defined
ERROR:django.server:"GET /myapp3/client_orders/10/ HTTP/1.1" 500 66301
ERROR:django.request:Internal Server Error: /myapp3/client_orders/10/
Traceback (most recent call last):
  File "C:\Users\Aleksandr\PycharmProjects\Django_project_2\venv\lib\site-packages\django\core\handlers\exception.py", line 55, in inner
    response = get_response(request)
  File "C:\Users\Aleksandr\PycharmProjects\Django_project_2\venv\lib\site-packages\django\core\handlers\base.py", line 197, in _get_response
    response = wrapped_callback(request, *callback_args, **callback_kwargs)
  File "C:\Users\Aleksandr\PycharmProjects\Django_project_2\myproject\myapp3\views.py", line 18, in client_orders
    seven_days_ago = timezone.now() - timedelta(days=7)
NameError: name 'timezone' is not defined
ERROR:django.server:"GET /myapp3/client_orders/10/ HTTP/1.1" 500 66301
INFO:django.utils.autoreload:C:\Users\Aleksandr\PycharmProjects\Django_project_2\myproject\myapp3\views.py changed, reloading.
INFO:django.server:"GET /myapp3/client_orders/10/ HTTP/1.1" 200 360
INFO:django.server:"GET /myapp3/client_orders/10/ HTTP/1.1" 200 360
INFO:django.utils.autoreload:C:\Users\Aleksandr\PycharmProjects\Django_project_2\myproject\myapp3\views.py changed, reloading.
INFO:django.utils.autoreload:C:\Users\Aleksandr\PycharmProjects\Django_project_2\myproject\myapp3\views.py changed, reloading.
INFO:django.server:"GET /myapp3/client_orders/10/ HTTP/1.1" 200 360
INFO:django.server:"GET /myapp3/client_orders/10/ HTTP/1.1" 200 360
INFO:django.server:"GET /myapp3/client_orders/10/ HTTP/1.1" 200 360
INFO:django.utils.autoreload:C:\Users\Aleksandr\PycharmProjects\Django_project_2\myproject\myapp3\views.py changed, reloading.
INFO:django.server:"GET /myapp3/client_orders/10/ HTTP/1.1" 200 360
INFO:django.server:"GET /myapp3/client_orders/10/ HTTP/1.1" 200 360
INFO:django.server:"GET /myapp3/client_orders/10/ HTTP/1.1" 200 360
INFO:django.server:"GET /myapp3/client_orders/10/ HTTP/1.1" 200 360
INFO:django.server:"GET /myapp3/client_orders/10/ HTTP/1.1" 200 360
INFO:django.utils.autoreload:C:\Users\Aleksandr\PycharmProjects\Django_project_2\myproject\myapp3\views.py changed, reloading.
INFO:django.server:"GET /myapp3/client_orders/10/ HTTP/1.1" 200 360
INFO:django.server:"GET /myapp3/client_orders/10/ HTTP/1.1" 200 360
INFO:django.server:"GET /myapp3/client_orders/10/ HTTP/1.1" 200 360
INFO:django.utils.autoreload:C:\Users\Aleksandr\PycharmProjects\Django_project_2\myproject\myapp3\views.py changed, reloading.
ERROR:django.request:Internal Server Error: /myapp3/client_orders/10/
Traceback (most recent call last):
  File "C:\Users\Aleksandr\PycharmProjects\Django_project_2\venv\lib\site-packages\django\core\handlers\exception.py", line 55, in inner
    response = get_response(request)
  File "C:\Users\Aleksandr\PycharmProjects\Django_project_2\venv\lib\site-packages\django\core\handlers\base.py", line 197, in _get_response
    response = wrapped_callback(request, *callback_args, **callback_kwargs)
  File "C:\Users\Aleksandr\PycharmProjects\Django_project_2\myproject\myapp3\views.py", line 32, in client_orders
    return render(request, 'orders.html', context)
NameError: name 'render' is not defined
ERROR:django.server:"GET /myapp3/client_orders/10/ HTTP/1.1" 500 67772
INFO:django.utils.autoreload:C:\Users\Aleksandr\PycharmProjects\Django_project_2\myproject\myapp3\views.py changed, reloading.
INFO:django.server:"GET /myapp3/client_orders/10/ HTTP/1.1" 200 360
INFO:django.server:"GET /myapp3/client_orders/10/ HTTP/1.1" 200 360
INFO:django.server:"GET /myapp3/client_orders/10/ HTTP/1.1" 200 360
INFO:django.server:"GET /myapp3/client_orders/10/ HTTP/1.1" 200 360
INFO:django.server:"GET /myapp3/client_orders/10/ HTTP/1.1" 200 360
INFO:django.server:"GET /myapp3/client_orders/10/ HTTP/1.1" 200 360
INFO:django.server:"GET /myapp3/client_orders/10/ HTTP/1.1" 200 360
INFO:django.server:"GET /myapp3/client_orders/1 HTTP/1.1" 301 0
INFO:django.server:"GET /myapp3/client_orders/1/ HTTP/1.1" 200 360
INFO:django.server:"GET /myapp3/client_orders/1/ HTTP/1.1" 200 360
INFO:django.server:"GET /myapp3/client_orders/1/ HTTP/1.1" 200 360
INFO:django.server:"GET /myapp3/client_orders/1/ HTTP/1.1" 200 360
INFO:django.server:"GET /myapp3/client_orders/1/ HTTP/1.1" 200 360
INFO:django.server:"GET /myapp3/client_orders/1/ HTTP/1.1" 200 360
INFO:django.server:"GET /myapp3/client_orders/1/ HTTP/1.1" 200 360
INFO:django.utils.autoreload:C:\Users\Aleksandr\PycharmProjects\Django_project_2\myproject\myapp3\views.py changed, reloading.
ERROR:django.request:Internal Server Error: /myapp3/client_orders/1/
Traceback (most recent call last):
  File "C:\Users\Aleksandr\PycharmProjects\Django_project_2\venv\lib\site-packages\django\core\handlers\exception.py", line 55, in inner
    response = get_response(request)
  File "C:\Users\Aleksandr\PycharmProjects\Django_project_2\venv\lib\site-packages\django\core\handlers\base.py", line 197, in _get_response
    response = wrapped_callback(request, *callback_args, **callback_kwargs)
  File "C:\Users\Aleksandr\PycharmProjects\Django_project_2\myproject\myapp3\views.py", line 16, in client_orders
    seven_days_ago = timezone.now() - timedelta(days=7)
AttributeError: type object 'datetime.timezone' has no attribute 'now'
ERROR:django.server:"GET /myapp3/client_orders/1/ HTTP/1.1" 500 66453
INFO:django.utils.autoreload:C:\Users\Aleksandr\PycharmProjects\Django_project_2\myproject\myapp3\views.py changed, reloading.
INFO:django.server:"GET /myapp3/client_orders/1/ HTTP/1.1" 200 360
INFO:django.server:"GET /myapp3/client_orders/1/ HTTP/1.1" 200 360
INFO:django.utils.autoreload:C:\Users\Aleksandr\PycharmProjects\Django_project_2\myproject\myapp3\views.py changed, reloading.
INFO:root:Посещена страница myapp3
INFO:django.server:"GET /myapp3/ HTTP/1.1" 200 337
WARNING:django.request:Not Found: /myapp3/2
WARNING:django.server:"GET /myapp3/2 HTTP/1.1" 404 2813
INFO:django.server:"GET /myapp3/client_orders/10/ HTTP/1.1" 200 360
INFO:django.server:"GET /myapp3/client_orders/10/ HTTP/1.1" 200 360
INFO:django.server:"GET /myapp3/client_orders/10/ HTTP/1.1" 200 360
INFO:django.utils.autoreload:C:\Users\Aleksandr\PycharmProjects\Django_project_2\myproject\myapp3\views.py changed, reloading.
INFO:django.server:"GET /myapp3/client_orders/10/ HTTP/1.1" 200 360
INFO:django.server:"GET /myapp3/client_orders/10/ HTTP/1.1" 200 360
INFO:django.server:"GET /myapp3/client_orders/10/ HTTP/1.1" 200 360
INFO:django.server:"GET /myapp3/client_orders/10/ HTTP/1.1" 200 360
INFO:django.server:"GET /myapp3/client_orders/10/ HTTP/1.1" 200 388
INFO:root:Посещена главная страница
INFO:django.server:"GET / HTTP/1.1" 200 388
WARNING:django.request:Not Found: /favicon.ico
WARNING:django.server:"GET /favicon.ico HTTP/1.1" 404 2548
WARNING:django.request:Not Found: /myapp2/
WARNING:django.server:"GET /myapp2/ HTTP/1.1" 404 2536
INFO:root:Посещена страница myapp3
INFO:django.server:"GET /myapp3/ HTTP/1.1" 200 337
INFO:django.server:"GET /myapp3/client_orders/5/ HTTP/1.1" 200 388
INFO:django.server:"GET /myapp3/client_orders/6/ HTTP/1.1" 200 772
INFO:django.server:"GET /myapp3/client_orders/7/ HTTP/1.1" 200 388
INFO:django.server:"GET /myapp3/client_orders/8/ HTTP/1.1" 200 388
INFO:django.server:"GET /myapp3/client_orders/6/ HTTP/1.1" 200 772
INFO:django.server:"GET /myapp3/client_orders/7/ HTTP/1.1" 200 388
INFO:root:Посещена главная страница
INFO:django.server:"GET / HTTP/1.1" 200 388
WARNING:django.request:Not Found: /favicon.ico
WARNING:django.server:"GET /favicon.ico HTTP/1.1" 404 2655
WARNING:django.request:Not Found: /myapp4/
WARNING:django.server:"GET /myapp4/ HTTP/1.1" 404 2717
ERROR:django.request:Internal Server Error: /myapp4/user/add/
Traceback (most recent call last):
  File "C:\Users\Aleksandr\PycharmProjects\Django_project_2\venv\lib\site-packages\django\core\handlers\exception.py", line 55, in inner
    response = get_response(request)
  File "C:\Users\Aleksandr\PycharmProjects\Django_project_2\venv\lib\site-packages\django\core\handlers\base.py", line 197, in _get_response
    response = wrapped_callback(request, *callback_args, **callback_kwargs)
  File "C:\Users\Aleksandr\PycharmProjects\Django_project_2\myproject\myapp4\views.py", line 20, in form_app4
    return render(request, 'myapp4/form_app4.html', {'form': form})
  File "C:\Users\Aleksandr\PycharmProjects\Django_project_2\venv\lib\site-packages\django\shortcuts.py", line 25, in render
    content = loader.render_to_string(template_name, context, request, using=using)
  File "C:\Users\Aleksandr\PycharmProjects\Django_project_2\venv\lib\site-packages\django\template\loader.py", line 61, in render_to_string
    template = get_template(template_name, using=using)
  File "C:\Users\Aleksandr\PycharmProjects\Django_project_2\venv\lib\site-packages\django\template\loader.py", line 19, in get_template
    raise TemplateDoesNotExist(template_name, chain=chain)
django.template.exceptions.TemplateDoesNotExist: myapp4/form_app4.html
ERROR:django.server:"GET /myapp4/user/add/ HTTP/1.1" 500 81161
WARNING:django.request:Not Found: /user/add/
WARNING:django.server:"GET /user/add/ HTTP/1.1" 404 2649
INFO:django.utils.autoreload:C:\Users\Aleksandr\PycharmProjects\Django_project_2\myproject\myproject\urls.py changed, reloading.
ERROR:django.request:Internal Server Error: /user/add/
Traceback (most recent call last):
  File "C:\Users\Aleksandr\PycharmProjects\Django_project_2\venv\lib\site-packages\django\core\handlers\exception.py", line 55, in inner
    response = get_response(request)
  File "C:\Users\Aleksandr\PycharmProjects\Django_project_2\venv\lib\site-packages\django\core\handlers\base.py", line 197, in _get_response
    response = wrapped_callback(request, *callback_args, **callback_kwargs)
  File "C:\Users\Aleksandr\PycharmProjects\Django_project_2\myproject\myapp4\views.py", line 20, in form_app4
    return render(request, 'myapp4/form_app4.html', {'form': form})
  File "C:\Users\Aleksandr\PycharmProjects\Django_project_2\venv\lib\site-packages\django\shortcuts.py", line 25, in render
    content = loader.render_to_string(template_name, context, request, using=using)
  File "C:\Users\Aleksandr\PycharmProjects\Django_project_2\venv\lib\site-packages\django\template\loader.py", line 61, in render_to_string
    template = get_template(template_name, using=using)
  File "C:\Users\Aleksandr\PycharmProjects\Django_project_2\venv\lib\site-packages\django\template\loader.py", line 19, in get_template
    raise TemplateDoesNotExist(template_name, chain=chain)
django.template.exceptions.TemplateDoesNotExist: myapp4/form_app4.html
ERROR:django.server:"GET /user/add/ HTTP/1.1" 500 81214
INFO:django.utils.autoreload:C:\Users\Aleksandr\PycharmProjects\Django_project_2\myproject\myapp4\views.py changed, reloading.
INFO:django.server:"GET /user/add/ HTTP/1.1" 200 729
INFO:django.server:"GET /user/add/ HTTP/1.1" 200 776
INFO:myapp4.views:Получили name='Василий', email='sffsdgg1@mail.ru', age=21.
INFO:django.server:"POST /user/add/ HTTP/1.1" 200 835
INFO:myapp4.views:Получили name='Василий', email='sffsdgg1@mail.ru', age=21.
INFO:django.server:"POST /user/add/ HTTP/1.1" 200 835
INFO:root:Посещена главная страница
INFO:django.server:"GET / HTTP/1.1" 200 388
WARNING:django.request:Not Found: /users/
WARNING:django.server:"GET /users/ HTTP/1.1" 404 2707
WARNING:django.request:Not Found: /users/add/
WARNING:django.server:"GET /users/add/ HTTP/1.1" 404 2719
WARNING:django.request:Not Found: /users/add/
WARNING:django.server:"GET /users/add/ HTTP/1.1" 404 2719
INFO:django.server:"GET /user/add/ HTTP/1.1" 200 776
INFO:myapp4.views:Получили name='name12', email='sffsdgg2@mail.ru', age=20.
INFO:django.server:"POST /user/add/ HTTP/1.1" 200 827
INFO:myapp4.views:Получили name='name12', email='sffsdgg2@mail.ru', age=20.
INFO:django.server:"POST /user/add/ HTTP/1.1" 200 827
INFO:myapp4.views:Получили name='name12', email='sffsdgg2@mail.ru', age=20.
INFO:django.server:"POST /user/add/ HTTP/1.1" 200 827
INFO:myapp4.views:Получили name='name12', email='sffsdgg2@mail.ru', age=20.
INFO:django.server:"POST /user/add/ HTTP/1.1" 200 827
INFO:myapp4.views:Получили name='name12', email='sffsdgg2@mail.ru', age=20.
INFO:django.server:"POST /user/add/ HTTP/1.1" 200 827
INFO:myapp4.views:Получили name='name12', email='sffsdgg2@mail.ru', age=20.
INFO:django.server:"POST /user/add/ HTTP/1.1" 200 827
INFO:root:Посещена главная страница
INFO:django.server:"GET / HTTP/1.1" 200 388
INFO:root:Посещена главная страница
INFO:django.server:"GET / HTTP/1.1" 200 388
INFO:root:Посещена главная страница
INFO:django.server:"GET / HTTP/1.1" 200 388
INFO:root:Посещена главная страница
INFO:django.server:"GET / HTTP/1.1" 200 388
INFO:django.utils.autoreload:C:\Users\Aleksandr\PycharmProjects\Django_project_2\myproject\myapp4\views.py changed, reloading.
INFO:django.utils.autoreload:C:\Users\Aleksandr\PycharmProjects\Django_project_2\myproject\myproject\settings.py changed, reloading.
INFO:root:Посещена главная страница
INFO:django.server:"GET / HTTP/1.1" 200 388
INFO:root:Посещена главная страница
INFO:django.server:"GET / HTTP/1.1" 200 388
INFO:root:Посещена главная страница
INFO:django.server:"GET / HTTP/1.1" 200 388
INFO:root:Посещена главная страница
INFO:django.server:"GET / HTTP/1.1" 200 388
INFO:root:Посещена главная страница
INFO:django.server:"GET / HTTP/1.1" 200 388
INFO:root:Посещена главная страница
INFO:django.server:"GET / HTTP/1.1" 200 388
INFO:django.utils.autoreload:C:\Users\Aleksandr\PycharmProjects\Django_project_2\myproject\myapp4\views.py changed, reloading.
INFO:root:Посещена главная страница
INFO:django.server:"GET / HTTP/1.1" 200 388
INFO:root:Посещена главная страница
INFO:django.server:"GET / HTTP/1.1" 200 388
INFO:root:Посещена главная страница
INFO:django.server:"GET / HTTP/1.1" 200 388
INFO:root:Посещена главная страница
INFO:django.server:"GET / HTTP/1.1" 200 388
INFO:root:Посещена главная страница
INFO:django.server:"GET / HTTP/1.1" 200 388
INFO:root:Посещена главная страница
INFO:django.server:"GET / HTTP/1.1" 200 388
INFO:root:Посещена главная страница
INFO:django.server:"GET / HTTP/1.1" 200 388
INFO:root:Посещена главная страница
INFO:django.server:"GET / HTTP/1.1" 200 388
INFO:root:Посещена главная страница
INFO:django.server:"GET / HTTP/1.1" 200 388
INFO:root:Посещена главная страница
INFO:django.server:"GET / HTTP/1.1" 200 388
INFO:root:Посещена главная страница
INFO:django.server:"GET / HTTP/1.1" 200 388
INFO:root:Посещена главная страница
INFO:django.server:"GET / HTTP/1.1" 200 388
INFO:root:Посещена главная страница
INFO:django.server:"GET / HTTP/1.1" 200 388
INFO:root:Посещена главная страница
INFO:django.server:"GET / HTTP/1.1" 200 388
INFO:django.utils.autoreload:C:\Users\Aleksandr\PycharmProjects\Django_project_2\myproject\myapp4\views.py changed, reloading.
INFO:root:Посещена главная страница
INFO:django.server:"GET / HTTP/1.1" 200 388
INFO:root:Посещена главная страница
INFO:django.server:"GET / HTTP/1.1" 200 388
INFO:root:Посещена главная страница
INFO:django.server:"GET / HTTP/1.1" 200 388
INFO:root:Посещена главная страница
INFO:django.server:"GET / HTTP/1.1" 200 388
INFO:django.utils.autoreload:C:\Users\Aleksandr\PycharmProjects\Django_project_2\myproject\myapp4\views.py changed, reloading.
INFO:django.server:"GET /user/add/ HTTP/1.1" 200 776
INFO:myapp4.views:Получили name='name12', email='sffsdgg2@mail.ru', age=28.
INFO:django.server:"POST /user/add/ HTTP/1.1" 200 827
INFO:myapp4.views:Получили name='name12', email='sffsdgg2@mail.ru', age=28.
INFO:django.server:"POST /user/add/ HTTP/1.1" 200 827
INFO:django.utils.autoreload:C:\Users\Aleksandr\PycharmProjects\Django_project_2\myproject\myapp4\forms.py changed, reloading.
INFO:django.utils.autoreload:C:\Users\Aleksandr\PycharmProjects\Django_project_2\myproject\myapp4\forms.py changed, reloading.
INFO:django.utils.autoreload:C:\Users\Aleksandr\PycharmProjects\Django_project_2\myproject\myapp4\urls.py changed, reloading.
INFO:django.server:"GET /add/ HTTP/1.1" 200 776
INFO:myapp4.views:Получили name='tadles5', email='sffsdgg11@mail.ru', age=24.
INFO:django.server:"POST /add/ HTTP/1.1" 200 829
INFO:django.utils.autoreload:C:\Users\Aleksandr\PycharmProjects\Django_project_2\myproject\myapp4\views.py changed, reloading.
INFO:django.utils.autoreload:C:\Users\Aleksandr\PycharmProjects\Django_project_2\myproject\myapp4\views.py changed, reloading.
INFO:django.utils.autoreload:C:\Users\Aleksandr\PycharmProjects\Django_project_2\myproject\myapp4\urls.py changed, reloading.
ERROR:django.request:Internal Server Error: /add2/
Traceback (most recent call last):
  File "C:\Users\Aleksandr\PycharmProjects\Django_project_2\venv\lib\site-packages\django\core\handlers\exception.py", line 55, in inner
    response = get_response(request)
  File "C:\Users\Aleksandr\PycharmProjects\Django_project_2\venv\lib\site-packages\django\core\handlers\base.py", line 197, in _get_response
    response = wrapped_callback(request, *callback_args, **callback_kwargs)
  File "C:\Users\Aleksandr\PycharmProjects\Django_project_2\myproject\myapp4\views.py", line 31, in form2_app4
    return render(request, 'form2_app4.html', {'form': form})
  File "C:\Users\Aleksandr\PycharmProjects\Django_project_2\venv\lib\site-packages\django\shortcuts.py", line 25, in render
    content = loader.render_to_string(template_name, context, request, using=using)
  File "C:\Users\Aleksandr\PycharmProjects\Django_project_2\venv\lib\site-packages\django\template\loader.py", line 61, in render_to_string
    template = get_template(template_name, using=using)
  File "C:\Users\Aleksandr\PycharmProjects\Django_project_2\venv\lib\site-packages\django\template\loader.py", line 19, in get_template
    raise TemplateDoesNotExist(template_name, chain=chain)
django.template.exceptions.TemplateDoesNotExist: form2_app4.html
ERROR:django.server:"GET /add2/ HTTP/1.1" 500 80742
INFO:django.utils.autoreload:C:\Users\Aleksandr\PycharmProjects\Django_project_2\myproject\myapp4\forms.py changed, reloading.
INFO:django.server:"GET /add/ HTTP/1.1" 200 776
INFO:django.utils.autoreload:C:\Users\Aleksandr\PycharmProjects\Django_project_2\myproject\myapp4\urls.py changed, reloading.
ERROR:django.request:Internal Server Error: /add2/
Traceback (most recent call last):
  File "C:\Users\Aleksandr\PycharmProjects\Django_project_2\venv\lib\site-packages\django\core\handlers\exception.py", line 55, in inner
    response = get_response(request)
  File "C:\Users\Aleksandr\PycharmProjects\Django_project_2\venv\lib\site-packages\django\core\handlers\base.py", line 197, in _get_response
    response = wrapped_callback(request, *callback_args, **callback_kwargs)
  File "C:\Users\Aleksandr\PycharmProjects\Django_project_2\myproject\myapp4\views.py", line 31, in form2_app4
    return render(request, 'form2_app4.html', {'form': form})
  File "C:\Users\Aleksandr\PycharmProjects\Django_project_2\venv\lib\site-packages\django\shortcuts.py", line 25, in render
    content = loader.render_to_string(template_name, context, request, using=using)
  File "C:\Users\Aleksandr\PycharmProjects\Django_project_2\venv\lib\site-packages\django\template\loader.py", line 61, in render_to_string
    template = get_template(template_name, using=using)
  File "C:\Users\Aleksandr\PycharmProjects\Django_project_2\venv\lib\site-packages\django\template\loader.py", line 19, in get_template
    raise TemplateDoesNotExist(template_name, chain=chain)
django.template.exceptions.TemplateDoesNotExist: form2_app4.html
ERROR:django.server:"GET /add2/ HTTP/1.1" 500 80742
INFO:django.utils.autoreload:C:\Users\Aleksandr\PycharmProjects\Django_project_2\myproject\myapp4\forms.py changed, reloading.
INFO:django.utils.autoreload:C:\Users\Aleksandr\PycharmProjects\Django_project_2\myproject\myapp4\forms.py changed, reloading.
ERROR:django.request:Internal Server Error: /add2/
Traceback (most recent call last):
  File "C:\Users\Aleksandr\PycharmProjects\Django_project_2\venv\lib\site-packages\django\core\handlers\exception.py", line 55, in inner
    response = get_response(request)
  File "C:\Users\Aleksandr\PycharmProjects\Django_project_2\venv\lib\site-packages\django\core\handlers\base.py", line 197, in _get_response
    response = wrapped_callback(request, *callback_args, **callback_kwargs)
  File "C:\Users\Aleksandr\PycharmProjects\Django_project_2\myproject\myapp4\views.py", line 31, in form2_app4
    return render(request, 'form2_app4.html', {'form': form})
  File "C:\Users\Aleksandr\PycharmProjects\Django_project_2\venv\lib\site-packages\django\shortcuts.py", line 25, in render
    content = loader.render_to_string(template_name, context, request, using=using)
  File "C:\Users\Aleksandr\PycharmProjects\Django_project_2\venv\lib\site-packages\django\template\loader.py", line 61, in render_to_string
    template = get_template(template_name, using=using)
  File "C:\Users\Aleksandr\PycharmProjects\Django_project_2\venv\lib\site-packages\django\template\loader.py", line 19, in get_template
    raise TemplateDoesNotExist(template_name, chain=chain)
django.template.exceptions.TemplateDoesNotExist: form2_app4.html
ERROR:django.server:"GET /add2/ HTTP/1.1" 500 80879
INFO:django.utils.autoreload:C:\Users\Aleksandr\PycharmProjects\Django_project_2\myproject\myproject\urls.py changed, reloading.
INFO:django.server:"GET /myapp4/add/ HTTP/1.1" 200 776
ERROR:django.request:Internal Server Error: /myapp4/add2/
Traceback (most recent call last):
  File "C:\Users\Aleksandr\PycharmProjects\Django_project_2\venv\lib\site-packages\django\core\handlers\exception.py", line 55, in inner
    response = get_response(request)
  File "C:\Users\Aleksandr\PycharmProjects\Django_project_2\venv\lib\site-packages\django\core\handlers\base.py", line 197, in _get_response
    response = wrapped_callback(request, *callback_args, **callback_kwargs)
  File "C:\Users\Aleksandr\PycharmProjects\Django_project_2\myproject\myapp4\views.py", line 31, in form2_app4
    return render(request, 'form2_app4.html', {'form': form})
  File "C:\Users\Aleksandr\PycharmProjects\Django_project_2\venv\lib\site-packages\django\shortcuts.py", line 25, in render
    content = loader.render_to_string(template_name, context, request, using=using)
  File "C:\Users\Aleksandr\PycharmProjects\Django_project_2\venv\lib\site-packages\django\template\loader.py", line 61, in render_to_string
    template = get_template(template_name, using=using)
  File "C:\Users\Aleksandr\PycharmProjects\Django_project_2\venv\lib\site-packages\django\template\loader.py", line 19, in get_template
    raise TemplateDoesNotExist(template_name, chain=chain)
django.template.exceptions.TemplateDoesNotExist: form2_app4.html
ERROR:django.server:"GET /myapp4/add2/ HTTP/1.1" 500 80826
INFO:django.server:"GET /myapp4/add/ HTTP/1.1" 200 776
INFO:django.utils.autoreload:C:\Users\Aleksandr\PycharmProjects\Django_project_2\myproject\myproject\settings.py changed, reloading.
INFO:django.utils.autoreload:C:\Users\Aleksandr\PycharmProjects\Django_project_2\myproject\myapp4\views.py changed, reloading.
INFO:django.utils.autoreload:C:\Users\Aleksandr\PycharmProjects\Django_project_2\myproject\myapp4\views.py changed, reloading.
INFO:django.utils.autoreload:C:\Users\Aleksandr\PycharmProjects\Django_project_2\myproject\myapp4\urls.py changed, reloading.
INFO:django.utils.autoreload:C:\Users\Aleksandr\PycharmProjects\Django_project_2\myproject\myapp4\views.py changed, reloading.
INFO:django.utils.autoreload:C:\Users\Aleksandr\PycharmProjects\Django_project_2\myproject\myapp4\urls.py changed, reloading.
ERROR:django.request:Internal Server Error: /myapp4/upload/
Traceback (most recent call last):
  File "C:\Users\Aleksandr\PycharmProjects\Django_project_2\venv\lib\site-packages\django\core\handlers\exception.py", line 55, in inner
    response = get_response(request)
  File "C:\Users\Aleksandr\PycharmProjects\Django_project_2\venv\lib\site-packages\django\core\handlers\base.py", line 197, in _get_response
    response = wrapped_callback(request, *callback_args, **callback_kwargs)
  File "C:\Users\Aleksandr\PycharmProjects\Django_project_2\myproject\myapp4\views.py", line 46, in upload_image
    return render(request, 'myapp4/upload_image.html', {'form':form})
  File "C:\Users\Aleksandr\PycharmProjects\Django_project_2\venv\lib\site-packages\django\shortcuts.py", line 25, in render
    content = loader.render_to_string(template_name, context, request, using=using)
  File "C:\Users\Aleksandr\PycharmProjects\Django_project_2\venv\lib\site-packages\django\template\loader.py", line 61, in render_to_string
    template = get_template(template_name, using=using)
  File "C:\Users\Aleksandr\PycharmProjects\Django_project_2\venv\lib\site-packages\django\template\loader.py", line 19, in get_template
    raise TemplateDoesNotExist(template_name, chain=chain)
django.template.exceptions.TemplateDoesNotExist: myapp4/upload_image.html
ERROR:django.server:"GET /myapp4/upload/ HTTP/1.1" 500 81187
INFO:django.server:"GET /myapp4/add/ HTTP/1.1" 200 776
INFO:django.utils.autoreload:C:\Users\Aleksandr\PycharmProjects\Django_project_2\myproject\myapp4\forms.py changed, reloading.
INFO:django.utils.autoreload:C:\Users\Aleksandr\PycharmProjects\Django_project_2\myproject\myapp4\urls.py changed, reloading.
INFO:django.utils.autoreload:C:\Users\Aleksandr\PycharmProjects\Django_project_2\myproject\myapp4\views.py changed, reloading.
INFO:django.utils.autoreload:C:\Users\Aleksandr\PycharmProjects\Django_project_2\myproject\myapp4\urls.py changed, reloading.
ERROR:django.request:Internal Server Error: /myapp4/add/
Traceback (most recent call last):
  File "C:\Users\Aleksandr\PycharmProjects\Django_project_2\venv\lib\site-packages\django\core\handlers\exception.py", line 55, in inner
    response = get_response(request)
  File "C:\Users\Aleksandr\PycharmProjects\Django_project_2\venv\lib\site-packages\django\core\handlers\base.py", line 197, in _get_response
    response = wrapped_callback(request, *callback_args, **callback_kwargs)
  File "C:\Users\Aleksandr\PycharmProjects\Django_project_2\myproject\myapp4\views.py", line 22, in form_app4
    form = UserForm()
NameError: name 'UserForm' is not defined
ERROR:django.server:"GET /myapp4/add/ HTTP/1.1" 500 65954
INFO:django.utils.autoreload:C:\Users\Aleksandr\PycharmProjects\Django_project_2\myproject\myapp4\forms.py changed, reloading.
ERROR:django.request:Internal Server Error: /myapp4/add/
Traceback (most recent call last):
  File "C:\Users\Aleksandr\PycharmProjects\Django_project_2\venv\lib\site-packages\django\core\handlers\exception.py", line 55, in inner
    response = get_response(request)
  File "C:\Users\Aleksandr\PycharmProjects\Django_project_2\venv\lib\site-packages\django\core\handlers\base.py", line 197, in _get_response
    response = wrapped_callback(request, *callback_args, **callback_kwargs)
  File "C:\Users\Aleksandr\PycharmProjects\Django_project_2\myproject\myapp4\views.py", line 22, in form_app4
    form = UserForm()
NameError: name 'UserForm' is not defined
ERROR:django.server:"GET /myapp4/add/ HTTP/1.1" 500 65954
ERROR:django.request:Internal Server Error: /myapp4/add/
Traceback (most recent call last):
  File "C:\Users\Aleksandr\PycharmProjects\Django_project_2\venv\lib\site-packages\django\core\handlers\exception.py", line 55, in inner
    response = get_response(request)
  File "C:\Users\Aleksandr\PycharmProjects\Django_project_2\venv\lib\site-packages\django\core\handlers\base.py", line 197, in _get_response
    response = wrapped_callback(request, *callback_args, **callback_kwargs)
  File "C:\Users\Aleksandr\PycharmProjects\Django_project_2\myproject\myapp4\views.py", line 22, in form_app4
    form = UserForm()
NameError: name 'UserForm' is not defined
ERROR:django.server:"GET /myapp4/add/ HTTP/1.1" 500 65954
INFO:django.utils.autoreload:C:\Users\Aleksandr\PycharmProjects\Django_project_2\myproject\myapp4\views.py changed, reloading.
INFO:django.server:"GET /myapp4/add/ HTTP/1.1" 200 776
ERROR:django.request:Internal Server Error: /myapp4/upload/
Traceback (most recent call last):
  File "C:\Users\Aleksandr\PycharmProjects\Django_project_2\venv\lib\site-packages\django\core\handlers\exception.py", line 55, in inner
    response = get_response(request)
  File "C:\Users\Aleksandr\PycharmProjects\Django_project_2\venv\lib\site-packages\django\core\handlers\base.py", line 197, in _get_response
    response = wrapped_callback(request, *callback_args, **callback_kwargs)
  File "C:\Users\Aleksandr\PycharmProjects\Django_project_2\myproject\myapp4\views.py", line 46, in upload_image
    return render(request, 'upload_image.html', {'form':form})
  File "C:\Users\Aleksandr\PycharmProjects\Django_project_2\venv\lib\site-packages\django\shortcuts.py", line 25, in render
    content = loader.render_to_string(template_name, context, request, using=using)
  File "C:\Users\Aleksandr\PycharmProjects\Django_project_2\venv\lib\site-packages\django\template\loader.py", line 61, in render_to_string
    template = get_template(template_name, using=using)
  File "C:\Users\Aleksandr\PycharmProjects\Django_project_2\venv\lib\site-packages\django\template\loader.py", line 19, in get_template
    raise TemplateDoesNotExist(template_name, chain=chain)
django.template.exceptions.TemplateDoesNotExist: upload_image.html
ERROR:django.server:"GET /myapp4/upload/ HTTP/1.1" 500 81047
INFO:django.utils.autoreload:C:\Users\Aleksandr\PycharmProjects\Django_project_2\myproject\myapp4\urls.py changed, reloading.
ERROR:django.request:Internal Server Error: /myapp4/upload/
Traceback (most recent call last):
  File "C:\Users\Aleksandr\PycharmProjects\Django_project_2\venv\lib\site-packages\django\core\handlers\exception.py", line 55, in inner
    response = get_response(request)
  File "C:\Users\Aleksandr\PycharmProjects\Django_project_2\venv\lib\site-packages\django\core\handlers\base.py", line 197, in _get_response
    response = wrapped_callback(request, *callback_args, **callback_kwargs)
  File "C:\Users\Aleksandr\PycharmProjects\Django_project_2\myproject\myapp4\views.py", line 46, in upload_image
    return render(request, 'upload_image.html', {'form':form})
  File "C:\Users\Aleksandr\PycharmProjects\Django_project_2\venv\lib\site-packages\django\shortcuts.py", line 25, in render
    content = loader.render_to_string(template_name, context, request, using=using)
  File "C:\Users\Aleksandr\PycharmProjects\Django_project_2\venv\lib\site-packages\django\template\loader.py", line 61, in render_to_string
    template = get_template(template_name, using=using)
  File "C:\Users\Aleksandr\PycharmProjects\Django_project_2\venv\lib\site-packages\django\template\loader.py", line 19, in get_template
    raise TemplateDoesNotExist(template_name, chain=chain)
django.template.exceptions.TemplateDoesNotExist: upload_image.html
ERROR:django.server:"GET /myapp4/upload/ HTTP/1.1" 500 81184
ERROR:django.request:Internal Server Error: /myapp4/upload/
Traceback (most recent call last):
  File "C:\Users\Aleksandr\PycharmProjects\Django_project_2\venv\lib\site-packages\django\core\handlers\exception.py", line 55, in inner
    response = get_response(request)
  File "C:\Users\Aleksandr\PycharmProjects\Django_project_2\venv\lib\site-packages\django\core\handlers\base.py", line 197, in _get_response
    response = wrapped_callback(request, *callback_args, **callback_kwargs)
  File "C:\Users\Aleksandr\PycharmProjects\Django_project_2\myproject\myapp4\views.py", line 46, in upload_image
    return render(request, 'upload_image.html', {'form':form})
  File "C:\Users\Aleksandr\PycharmProjects\Django_project_2\venv\lib\site-packages\django\shortcuts.py", line 25, in render
    content = loader.render_to_string(template_name, context, request, using=using)
  File "C:\Users\Aleksandr\PycharmProjects\Django_project_2\venv\lib\site-packages\django\template\loader.py", line 61, in render_to_string
    template = get_template(template_name, using=using)
  File "C:\Users\Aleksandr\PycharmProjects\Django_project_2\venv\lib\site-packages\django\template\loader.py", line 19, in get_template
    raise TemplateDoesNotExist(template_name, chain=chain)
django.template.exceptions.TemplateDoesNotExist: upload_image.html
ERROR:django.server:"GET /myapp4/upload/ HTTP/1.1" 500 81184
INFO:django.server:"GET /myapp4/add/ HTTP/1.1" 200 776
INFO:django.server:"GET /myapp4/add/ HTTP/1.1" 200 776
INFO:django.utils.autoreload:C:\Users\Aleksandr\PycharmProjects\Django_project_2\myproject\myapp4\urls.py changed, reloading.
INFO:django.server:"GET /myapp4/add/ HTTP/1.1" 200 776
INFO:django.server:"GET /myapp4/add/upload/ HTTP/1.1" 200 587
ERROR:django.request:Internal Server Error: /myapp4/add/upload/
Traceback (most recent call last):
  File "C:\Users\Aleksandr\PycharmProjects\Django_project_2\venv\lib\site-packages\django\core\handlers\exception.py", line 55, in inner
    response = get_response(request)
  File "C:\Users\Aleksandr\PycharmProjects\Django_project_2\venv\lib\site-packages\django\core\handlers\base.py", line 197, in _get_response
    response = wrapped_callback(request, *callback_args, **callback_kwargs)
  File "C:\Users\Aleksandr\PycharmProjects\Django_project_2\myproject\myapp4\views.py", line 40, in upload_image
    if form.is_valid():
  File "C:\Users\Aleksandr\PycharmProjects\Django_project_2\venv\lib\site-packages\django\forms\forms.py", line 197, in is_valid
    return self.is_bound and not self.errors
  File "C:\Users\Aleksandr\PycharmProjects\Django_project_2\venv\lib\site-packages\django\forms\forms.py", line 192, in errors
    self.full_clean()
  File "C:\Users\Aleksandr\PycharmProjects\Django_project_2\venv\lib\site-packages\django\forms\forms.py", line 327, in full_clean
    self._clean_fields()
  File "C:\Users\Aleksandr\PycharmProjects\Django_project_2\venv\lib\site-packages\django\forms\forms.py", line 337, in _clean_fields
    value = field.clean(value, bf.initial)
  File "C:\Users\Aleksandr\PycharmProjects\Django_project_2\venv\lib\site-packages\django\forms\fields.py", line 689, in clean
    return super().clean(data)
  File "C:\Users\Aleksandr\PycharmProjects\Django_project_2\venv\lib\site-packages\django\forms\fields.py", line 204, in clean
    value = self.to_python(value)
  File "C:\Users\Aleksandr\PycharmProjects\Django_project_2\venv\lib\site-packages\django\forms\fields.py", line 716, in to_python
    from PIL import Image
ModuleNotFoundError: No module named 'PIL'
ERROR:django.server:"POST /myapp4/add/upload/ HTTP/1.1" 500 95079
ERROR:django.request:Internal Server Error: /myapp4/add/upload/
Traceback (most recent call last):
  File "C:\Users\Aleksandr\PycharmProjects\Django_project_2\venv\lib\site-packages\django\core\handlers\exception.py", line 55, in inner
    response = get_response(request)
  File "C:\Users\Aleksandr\PycharmProjects\Django_project_2\venv\lib\site-packages\django\core\handlers\base.py", line 197, in _get_response
    response = wrapped_callback(request, *callback_args, **callback_kwargs)
  File "C:\Users\Aleksandr\PycharmProjects\Django_project_2\myproject\myapp4\views.py", line 40, in upload_image
    if form.is_valid():
  File "C:\Users\Aleksandr\PycharmProjects\Django_project_2\venv\lib\site-packages\django\forms\forms.py", line 197, in is_valid
    return self.is_bound and not self.errors
  File "C:\Users\Aleksandr\PycharmProjects\Django_project_2\venv\lib\site-packages\django\forms\forms.py", line 192, in errors
    self.full_clean()
  File "C:\Users\Aleksandr\PycharmProjects\Django_project_2\venv\lib\site-packages\django\forms\forms.py", line 327, in full_clean
    self._clean_fields()
  File "C:\Users\Aleksandr\PycharmProjects\Django_project_2\venv\lib\site-packages\django\forms\forms.py", line 337, in _clean_fields
    value = field.clean(value, bf.initial)
  File "C:\Users\Aleksandr\PycharmProjects\Django_project_2\venv\lib\site-packages\django\forms\fields.py", line 689, in clean
    return super().clean(data)
  File "C:\Users\Aleksandr\PycharmProjects\Django_project_2\venv\lib\site-packages\django\forms\fields.py", line 204, in clean
    value = self.to_python(value)
  File "C:\Users\Aleksandr\PycharmProjects\Django_project_2\venv\lib\site-packages\django\forms\fields.py", line 716, in to_python
    from PIL import Image
ModuleNotFoundError: No module named 'PIL'
ERROR:django.server:"POST /myapp4/add/upload/ HTTP/1.1" 500 95079
INFO:django.server:"GET /myapp4/add/ HTTP/1.1" 200 776
INFO:django.server:"GET /myapp4/add/ HTTP/1.1" 200 776
INFO:django.server:"GET /myapp4/add/upload/ HTTP/1.1" 200 587
ERROR:django.request:Internal Server Error: /myapp4/add/upload/
Traceback (most recent call last):
  File "C:\Users\Aleksandr\PycharmProjects\Django_project_2\venv\lib\site-packages\django\core\handlers\exception.py", line 55, in inner
    response = get_response(request)
  File "C:\Users\Aleksandr\PycharmProjects\Django_project_2\venv\lib\site-packages\django\core\handlers\base.py", line 197, in _get_response
    response = wrapped_callback(request, *callback_args, **callback_kwargs)
  File "C:\Users\Aleksandr\PycharmProjects\Django_project_2\myproject\myapp4\views.py", line 40, in upload_image
    if form.is_valid():
  File "C:\Users\Aleksandr\PycharmProjects\Django_project_2\venv\lib\site-packages\django\forms\forms.py", line 197, in is_valid
    return self.is_bound and not self.errors
  File "C:\Users\Aleksandr\PycharmProjects\Django_project_2\venv\lib\site-packages\django\forms\forms.py", line 192, in errors
    self.full_clean()
  File "C:\Users\Aleksandr\PycharmProjects\Django_project_2\venv\lib\site-packages\django\forms\forms.py", line 327, in full_clean
    self._clean_fields()
  File "C:\Users\Aleksandr\PycharmProjects\Django_project_2\venv\lib\site-packages\django\forms\forms.py", line 337, in _clean_fields
    value = field.clean(value, bf.initial)
  File "C:\Users\Aleksandr\PycharmProjects\Django_project_2\venv\lib\site-packages\django\forms\fields.py", line 689, in clean
    return super().clean(data)
  File "C:\Users\Aleksandr\PycharmProjects\Django_project_2\venv\lib\site-packages\django\forms\fields.py", line 204, in clean
    value = self.to_python(value)
  File "C:\Users\Aleksandr\PycharmProjects\Django_project_2\venv\lib\site-packages\django\forms\fields.py", line 716, in to_python
    from PIL import Image
ModuleNotFoundError: No module named 'PIL'
ERROR:django.server:"POST /myapp4/add/upload/ HTTP/1.1" 500 95079
INFO:django.server:"POST /myapp4/add/upload/ HTTP/1.1" 200 587
INFO:django.server:"POST /myapp4/add/upload/ HTTP/1.1" 200 587
INFO:django.utils.autoreload:C:\Users\Aleksandr\PycharmProjects\Django_project_2\myproject\myapp4\urls.py changed, reloading.
INFO:django.utils.autoreload:C:\Users\Aleksandr\PycharmProjects\Django_project_2\myproject\myapp4\forms.py changed, reloading.
INFO:django.server:"GET /myapp4/add/ HTTP/1.1" 200 776
INFO:django.server:"GET /myapp4/add/add2 HTTP/1.1" 301 0
ERROR:django.request:Internal Server Error: /myapp4/add/add2/
Traceback (most recent call last):
  File "C:\Users\Aleksandr\PycharmProjects\Django_project_2\venv\lib\site-packages\django\core\handlers\exception.py", line 55, in inner
    response = get_response(request)
  File "C:\Users\Aleksandr\PycharmProjects\Django_project_2\venv\lib\site-packages\django\core\handlers\base.py", line 197, in _get_response
    response = wrapped_callback(request, *callback_args, **callback_kwargs)
  File "C:\Users\Aleksandr\PycharmProjects\Django_project_2\myproject\myapp4\views.py", line 34, in form2_app4
    return render(request, 'form2_app4.html', {'form': form})
  File "C:\Users\Aleksandr\PycharmProjects\Django_project_2\venv\lib\site-packages\django\shortcuts.py", line 25, in render
    content = loader.render_to_string(template_name, context, request, using=using)
  File "C:\Users\Aleksandr\PycharmProjects\Django_project_2\venv\lib\site-packages\django\template\loader.py", line 61, in render_to_string
    template = get_template(template_name, using=using)
  File "C:\Users\Aleksandr\PycharmProjects\Django_project_2\venv\lib\site-packages\django\template\loader.py", line 19, in get_template
    raise TemplateDoesNotExist(template_name, chain=chain)
django.template.exceptions.TemplateDoesNotExist: form2_app4.html
ERROR:django.server:"GET /myapp4/add/add2/ HTTP/1.1" 500 81934
INFO:django.utils.autoreload:C:\Users\Aleksandr\PycharmProjects\Django_project_2\myproject\myapp4\urls.py changed, reloading.
INFO:django.server:"GET /myapp4/add/add2/form HTTP/1.1" 301 0
ERROR:django.request:Internal Server Error: /myapp4/add/add2/form/
Traceback (most recent call last):
  File "C:\Users\Aleksandr\PycharmProjects\Django_project_2\venv\lib\site-packages\django\core\handlers\exception.py", line 55, in inner
    response = get_response(request)
  File "C:\Users\Aleksandr\PycharmProjects\Django_project_2\venv\lib\site-packages\django\core\handlers\base.py", line 197, in _get_response
    response = wrapped_callback(request, *callback_args, **callback_kwargs)
  File "C:\Users\Aleksandr\PycharmProjects\Django_project_2\myproject\myapp4\views.py", line 34, in form2_app4
    return render(request, 'form2_app4.html', {'form': form})
  File "C:\Users\Aleksandr\PycharmProjects\Django_project_2\venv\lib\site-packages\django\shortcuts.py", line 25, in render
    content = loader.render_to_string(template_name, context, request, using=using)
  File "C:\Users\Aleksandr\PycharmProjects\Django_project_2\venv\lib\site-packages\django\template\loader.py", line 61, in render_to_string
    template = get_template(template_name, using=using)
  File "C:\Users\Aleksandr\PycharmProjects\Django_project_2\venv\lib\site-packages\django\template\loader.py", line 19, in get_template
    raise TemplateDoesNotExist(template_name, chain=chain)
django.template.exceptions.TemplateDoesNotExist: form2_app4.html
ERROR:django.server:"GET /myapp4/add/add2/form/ HTTP/1.1" 500 81994
INFO:django.utils.autoreload:C:\Users\Aleksandr\PycharmProjects\Django_project_2\myproject\myapp4\urls.py changed, reloading.
INFO:django.server:"GET /myapp4/add/ HTTP/1.1" 200 776
INFO:django.server:"GET /myapp4/add2 HTTP/1.1" 301 0
ERROR:django.request:Internal Server Error: /myapp4/add2/
Traceback (most recent call last):
  File "C:\Users\Aleksandr\PycharmProjects\Django_project_2\venv\lib\site-packages\django\core\handlers\exception.py", line 55, in inner
    response = get_response(request)
  File "C:\Users\Aleksandr\PycharmProjects\Django_project_2\venv\lib\site-packages\django\core\handlers\base.py", line 197, in _get_response
    response = wrapped_callback(request, *callback_args, **callback_kwargs)
  File "C:\Users\Aleksandr\PycharmProjects\Django_project_2\myproject\myapp4\views.py", line 34, in form2_app4
    return render(request, 'form2_app4.html', {'form': form})
  File "C:\Users\Aleksandr\PycharmProjects\Django_project_2\venv\lib\site-packages\django\shortcuts.py", line 25, in render
    content = loader.render_to_string(template_name, context, request, using=using)
  File "C:\Users\Aleksandr\PycharmProjects\Django_project_2\venv\lib\site-packages\django\template\loader.py", line 61, in render_to_string
    template = get_template(template_name, using=using)
  File "C:\Users\Aleksandr\PycharmProjects\Django_project_2\venv\lib\site-packages\django\template\loader.py", line 19, in get_template
    raise TemplateDoesNotExist(template_name, chain=chain)
django.template.exceptions.TemplateDoesNotExist: form2_app4.html
ERROR:django.server:"GET /myapp4/add2/ HTTP/1.1" 500 81886
INFO:django.utils.autoreload:C:\Users\Aleksandr\PycharmProjects\Django_project_2\myproject\myapp4\urls.py changed, reloading.
INFO:django.utils.autoreload:C:\Users\Aleksandr\PycharmProjects\Django_project_2\myproject\myapp4\forms.py changed, reloading.
INFO:django.utils.autoreload:C:\Users\Aleksandr\PycharmProjects\Django_project_2\myproject\myapp4\views.py changed, reloading.
INFO:django.utils.autoreload:C:\Users\Aleksandr\PycharmProjects\Django_project_2\myproject\myapp4\views.py changed, reloading.
INFO:django.server:"GET /myapp4/add/upload/ HTTP/1.1" 200 587
INFO:django.server:"GET /myapp4/add/ HTTP/1.1" 200 776
INFO:django.server:"GET /myapp4/add/ HTTP/1.1" 200 776
INFO:root:Посещена главная страница
INFO:django.server:"GET / HTTP/1.1" 200 388
WARNING:django.request:Not Found: /favicon.ico
WARNING:django.server:"GET /favicon.ico HTTP/1.1" 404 2655
INFO:django.utils.autoreload:C:\Users\Aleksandr\PycharmProjects\Django_project_2\myproject\myapp4\urls.py changed, reloading.
INFO:root:Посещена главная страница
INFO:django.server:"GET / HTTP/1.1" 200 388
WARNING:django.request:Not Found: /add/
WARNING:django.server:"GET /add/ HTTP/1.1" 404 2634
WARNING:django.request:Not Found: /add/upload/
WARNING:django.server:"GET /add/upload/ HTTP/1.1" 404 2655
INFO:django.server:"GET /myapp4/add/ HTTP/1.1" 200 776
INFO:django.server:"GET /myapp4/add/upload/ HTTP/1.1" 200 587
WARNING:django.request:Not Found: /myapp4/add/upload_product_photo/
WARNING:django.server:"GET /myapp4/add/upload_product_photo/ HTTP/1.1" 404 3168
WARNING:django.request:Not Found: /myapp4/add/upload_product_photo/
WARNING:django.server:"GET /myapp4/add/upload_product_photo/ HTTP/1.1" 404 3168
INFO:django.server:"GET /myapp4/add/upload2/ HTTP/1.1" 200 1443
ERROR:django.request:Internal Server Error: /myapp4/add/upload2/
Traceback (most recent call last):
  File "C:\Users\Aleksandr\PycharmProjects\Django_project_2\venv\lib\site-packages\django\core\handlers\exception.py", line 55, in inner
    response = get_response(request)
  File "C:\Users\Aleksandr\PycharmProjects\Django_project_2\venv\lib\site-packages\django\core\handlers\base.py", line 197, in _get_response
    response = wrapped_callback(request, *callback_args, **callback_kwargs)
  File "C:\Users\Aleksandr\PycharmProjects\Django_project_2\myproject\myapp4\views.py", line 57, in upload_product_photo
    return redirect('product_detail', pk=product.pk)
  File "C:\Users\Aleksandr\PycharmProjects\Django_project_2\venv\lib\site-packages\django\shortcuts.py", line 49, in redirect
    return redirect_class(resolve_url(to, *args, **kwargs))
  File "C:\Users\Aleksandr\PycharmProjects\Django_project_2\venv\lib\site-packages\django\shortcuts.py", line 180, in resolve_url
    return reverse(to, args=args, kwargs=kwargs)
  File "C:\Users\Aleksandr\PycharmProjects\Django_project_2\venv\lib\site-packages\django\urls\base.py", line 88, in reverse
    return resolver._reverse_with_prefix(view, prefix, *args, **kwargs)
  File "C:\Users\Aleksandr\PycharmProjects\Django_project_2\venv\lib\site-packages\django\urls\resolvers.py", line 851, in _reverse_with_prefix
    raise NoReverseMatch(msg)
django.urls.exceptions.NoReverseMatch: Reverse for 'product_detail' not found. 'product_detail' is not a valid view function or pattern name.
ERROR:django.server:"POST /myapp4/add/upload2/ HTTP/1.1" 500 86180
